




try{
    const result = foo()
    console.log("after call to foo = ",result)
}catch(error){
    console.log('error message = ',error.message)
}
console.log("after try and catch")












